Workbook
Name List_Distributed: _xlfn.ANCHORARRAY('Customer Pricing'!$Z$1)
Name List_Manufactured: _xlfn.ANCHORARRAY('Customer Pricing'!$AA$1)
Name Mfr_Items_Lookup: _xlfn.ANCHORARRAY('Customer Pricing'!$AB$1)
Name Mfr_Prices_Lookup: _xlfn.ANCHORARRAY('Customer Pricing'!$AC$1)

Sheet Cost Master List
A1: Vendor Material | B1: WWI Product Code | C1: Price per kg (unit) | D1: Price per lb | E1: Incoterms | F1: Origin | G1: Vendor | H1: HTS code | I1: Tariff | J1: Freight in per kg | K1: Cert. cost/kg | L1: Landed cost per kg | M1: Landed cost per lb | N1: Margin | O1: Price/kg | P1: Price/lb | Q1: Strength | R1: Minimum | S1: Lead time
A2: Beta Carotene 1% pwd | B2: Natural Yellow G1301 (Nutracean China) | C2: 12 | D2: =C2/2.20462 -> 5.4431149 | E2: CIF NY | F2: China | G2: Nutracean | H2: 3204.18.0000 | I2: 0.381 | J2: 3 | K2: 0 | L2: =(C2*(1+I2))+J2 -> 19.572 | M2: =L2/2.20462 -> 8.8777204 | O2: =L2/(1-N2) -> 19.572 | P2: =O2/2.2 -> 8.8963636
A3: Beta Carotene 1% pwd | B3: Natural Yellow G1301 (Nutracean Slovenia) | C3: 13.4 | D3: =C3/2.20462 -> 6.078145 | E3: FCA | F3: Slovenia | G3: Nutracean | H3: 3204.18.0000 | I3: 0.03 | J3: 3 | K3: 0 | L3: =(C3*(1+I3))+J3 -> 16.802 | M3: =L3/2.20462 -> 7.6212681 | N3: 0.32 | O3: =L3/(1-N3) -> 24.708824 | P3: =O3/2.2 -> 11.231283
A4: Plantcol Annatto B4-SF | B4: Annatto Extract P2404 (Cyber Colors) | C4: 12.95 | D4: =C4/2.20462 -> 5.8740282 | E4: EXW Cork? | F4: Ireland | G4: Cybercolors | H4: 3203.00.1000 | I4: 0.15 | J4: 1.25 | K4: 0 | L4: =(C4*(1+I4))+J4 -> 16.1425 | M4: =L4/2.20462 -> 7.3221235 | N4: 0.3 | O4: =L4/(1-N4) -> 23.060714 | P4: =O4/2.2 -> 10.482143 | T4: Freight is $.85/kg to Chicago
A5: Annatto Extract WS5 | B5: Annatto Extract WS5 (Cyber Colors) | C5: 10.4 | D5: =C5/2.20462 -> 4.7173663 | E5: EXW Cork | F5: Ireland | G5: Cybercolors | H5: 3203.00.1000 | I5: 0.15 | J5: 1.5 | K5: 0 | L5: =(C5*(1+I5))+J5 -> 13.46 | M5: =L5/2.20462 -> 6.1053606
A6: Annatto suspension B8-SF | B6: Annatto Extract P2408 (Cyber Colors) | C6: 20.75 | D6: =C6/2.20462 -> 9.4120529 | E6: EXW Brazil | F6: Brazil | G6: Cybercolors | H6: 3203.00.1000 | I6: 0.5 | J6: 3.14 | K6: 0 | L6: =(C6*(1+I6))+J6 -> 34.265 | M6: =L6/2.20462 -> 15.542361 | N6: 0.32 | O6: =L6/(1-N6) -> 50.389706 | P6: =O6/2.2 -> 22.904412 | R6: 26.50 landed washmo | S6: 8 weeks | T6: Freight estimate given by vendor for 1 x 980kg IBC or 4 x 200kg drum into chicago
A7: Annatto Ext SSH03 | B7: Not Assigned | C7: 7.85 | D7: =C7/2.20462 -> 3.5607043 | E7: EXW Cork | F7: Ireland | G7: Cybercolors | H7: 3203.00.1000 | I7: 0.15 | J7: 4 | K7: 0 | L7: =(C7*(1+I7))+J7 -> 13.0275 | M7: =L7/2.20462 -> 5.9091816 | N7: 0.3 | O7: =L7/(1-N7) -> 18.610714 | P7: =O7/2.2 -> 8.4594156
A8: Chlorophyll AS1 | B8: Natural Green J1410 (Cyber Colors) | C8: 37.75 | D8: =C8/2.20462 -> 17.123132 | E8: CIF Chicago | F8: Ireland | G8: Cybercolors | H8: 3203.00.8000 | I8: 0.031 | J8: 6 | K8: 0 | L8: =(C8*(1+I8))+J8 -> 44.92025 | M8: =L8/2.20462 -> 20.375507 | N8: 0.25 | O8: =L8/(1-N8) -> 59.893667 | P8: =O8/2.2 -> 27.224394
A9: Carmine WSP1 | B9: Natural Red Q2350 (Cyber Colors) | C9: 345 | D9: =C9/2.20462 -> 156.48955 | E9: CIF Chicago | F9: Peru | G9: Cybercolors | H9: 3203.00.8000 | I9: 0.1 | J9: 4 | K9: 0 | L9: =(C9*(1+I9))+J9 -> 383.5 | M9: =L9/2.20462 -> 173.95288 | N9: 0.25 | O9: =L9/(1-N9) -> 511.33333 | P9: =O9/2.2 -> 232.42424
A10: Carmine WS4 | B10: Natural Red Q1304 (Cyber Colors) | C10: 64.64 | D10: =C10/2.20462 -> 29.320246 | E10: EXW Cork | F10: Ireland | G10: Cybercolors | H10: 3205.00.0500 | I10: 0.15 | J10: 1.5 | K10: 0 | L10: =(C10*(1+I10))+J10 -> 75.836 | M10: =L10/2.20462 -> 34.398672 | N10: 0.35 | O10: =L10/(1-N10) -> 116.67077 | P10: =O10/2.2 -> 53.032168
A11: Annatto powder 15% | B11: Annatto Extract P1315 (Imbarex) | C11: 58.5 | D11: =C11/2.20462 -> 26.535185 | E11: CIP Chicago | F11: Peru | G11: Imbarex | H11: 3203.00.1000 | I11: 0.1 | J11: 0.5 | K11: 0 | L11: =(C11*(1+I11))+J11 -> 64.85 | M11: =L11/2.20462 -> 29.4155 | N11: 0.1 | O11: =L11/(1-N11) -> 72.055556 | P11: =O11/2.2 -> 32.752525
A12: Annatto powder 15% | B12: Annatto Extract P1315 (IFF) | C12: 52.3 | D12: =C12/2.20462 -> 23.722909 | E12: EXW Lima | F12: Peru | G12: IFF | H12: 3203.00.1000 | I12: 0.1 | K12: 0 | L12: =(C12*(1+I12))+J12 -> 57.53 | M12: =L12/2.20462 -> 26.0952 | N12: 0.175 | O12: =L12/(1-N12) -> 69.733333 | P12: =O12/2.2 -> 31.69697
A13: FD&C Yellow 5 powder | B13: FD&C Yellow 5 Powder (Vidhi) | C13: 5.3 | D13: =C13/2.20462 -> 2.4040424 | E13: CIF NY | F13: India | G13: Vidhi | H13: 3204.12.5020 | I13: 0.565 | J13: 1.25 | K13: 1 | L13: =(C13*(1+I13))+J13+K13 -> 10.5445 | M13: =L13/2.20462 -> 4.7829104 | N13: 0.3 | O13: =L13/(1-N13) -> 15.063571 | P13: =O13/2.2 -> 6.8470779 | S13: 8 weeks
A14: FD&C Yellow 6 powder | B14: FD&C Yellow 6 Powder (Vidhi) | C14: 4.8 | D14: =C14/2.20462 -> 2.177246 | E14: CIF NY | F14: India | G14: Vidhi | H14: 3204.12.5020 | I14: 0.565 | J14: 1.25 | K14: 1 | L14: =(C14*(1+I14))+J14+K14 -> 9.762 | M14: =L14/2.20462 -> 4.427974 | N14: 0.3 | O14: =L14/(1-N14) -> 13.945714 | P14: =O14/2.2 -> 6.338961 | S14: 8 weeks
A15: FD&C Blue 1 powder | B15: FD&C Blue 1 Powder (Vidhi) | C15: 15.8 | D15: =C15/2.20462 -> 7.166768 | E15: CIF NY | F15: India | G15: Vidhi | H15: 3204.12.5090 | I15: 0.565 | J15: 1.25 | K15: 1 | L15: =(C15*(1+I15))+J15+K15 -> 26.977 | M15: =L15/2.20462 -> 12.236576 | N15: 0.3 | O15: =L15/(1-N15) -> 38.538571 | P15: =O15/2.2 -> 17.517532 | S15: 8 weeks
A16: FD%C Red 40 granular | B16: FD&C Red 40 Granular (Vidhi) | C16: 9.3 | D16: =C16/2.20462 -> 4.2184141 | E16: CIF NY | F16: India | G16: Vidhi | H16: 3204.12.5010 | I16: 0.565 | J16: 1.25 | K16: 1 | L16: =(C16*(1+I16))+J16+K16 -> 16.8045 | M16: =L16/2.20462 -> 7.622402 | N16: 0.3 | O16: =L16/(1-N16) -> 24.006429 | P16: =O16/2.2 -> 10.912013 | S16: 8 weeks
A17: FD&C Red 3 powder | B17: FD&C Red 3 Powder (Vidhi) | C17: 71.2 | D17: =C17/2.20462 -> 32.295815 | E17: CIF NY | F17: India | G17: Vidhi | H17: 3204.16.10 | I17: 0.565 | J17: 1.25 | K17: 1 | L17: =(C17*(1+I17))+J17+K17 -> 113.678 | M17: =L17/2.20462 -> 51.563535 | N17: 0.25 | O17: =L17/(1-N17) -> 151.57067 | P17: =O17/2.2 -> 68.895758 | S17: 8 weeks
A18: FD&C Red 40 HD Lake | B18: FD&C Red 40 HD Lake (Vidhi) | C18: 14.7 | D18: =C18/2.20462 -> 6.6678158 | E18: CIF NY | F18: India | G18: Vidhi | H18: 3205.00.5020 | I18: 0.565 | J18: 1.25 | K18: 1 | L18: =(C18*(1+I18))+J18+K18 -> 25.2555 | M18: =L18/2.20462 -> 11.455716 | N18: 0.3 | O18: =L18/(1-N18) -> 36.079286 | P18: =O18/2.2 -> 16.399675 | S18: 8 weeks
A19: FD&C Blue 1 powder | B19: FD&C Blue 1 Powder (Vivify) | C19: 29 | D19: =C19/2.20462 -> 13.154194 | E19: FCA Glendale Heights, IL | F19: India | G19: Vivify | I19: 0 | J19: 0.75 | K19: 1 | L19: =(C19*(1+I19))+J19+K19 -> 30.75 | M19: =L19/2.20462 -> 13.947982 | N19: 0.25 | O19: =L19/(1-N19) -> 41 | P19: =O19/2.2 -> 18.636364
A20: FD&C Yellow 5 powder | B20: FD&C Yellow 5 Powder (Vivify) | C20: 10.02 | D20: =C20/2.20462 -> 4.545001 | E20: FCA Glendale Heights, IL | F20: India | G20: Vivify | I20: 0 | J20: 0.75 | K20: 1 | L20: =(C20*(1+I20))+J20+K20 -> 11.77 | M20: =L20/2.20462 -> 5.3387885 | N20: 0.3 | O20: =L20/(1-N20) -> 16.814286 | P20: =O20/2.2 -> 7.6428571
A21: Amaranth | B21: Amaranth (Vidhi) | C21: 7.6 | D21: =C21/2.20462 -> 3.4473061 | E21: CIF NY | F21: India | G21: Vidhi | H21: ?? | J21: 1.25 | K21: 0 | L21: =(C21*(1+I21))+J21+K21 -> 8.85 | M21: =L21/2.20462 -> 4.0142972 | N21: 0.3 | O21: =L21/(1-N21) -> 12.642857 | P21: =O21/2.2 -> 5.7467532
A22: Spirulina Extract E18 | B22: Natural Blue L1300 (Hiche) | C22: 80 | D22: =C22/2.20462 -> 36.287433 | E22: FOB Qingdao | F22: China | G22: Qingdao | H22: 3203.00.8000 | I22: 0.381 | J22: 3 | K22: 0 | L22: =(C22*(1+I22))+J22 -> 113.48 | M22: =L22/2.20462 -> 51.473723 | N22: 0.485 | O22: =L22/(1-N22) -> 220.34951 | P22: =O22/2.2 -> 100.15887 | Q22: 200-300
A23: Radish | B23: Radish (Hiche) | C23: 56 | D23: =C23/2.20462 -> 25.401203 | E23: FOB Qingdao | F23: China | G23: Qingdao | H23: 3203.00.8000 | I23: 0.381 | J23: 3 | K23: 0 | L23: =(C23*(1+I23))+J23 -> 80.336 | M23: =L23/2.20462 -> 36.43984 | N23: 0.55 | O23: =L23/(1-N23) -> 178.52444 | P23: =O23/2.2 -> 81.147475 | Q23: 800CV
A24: PSP | B24: Purple Sweet Potato (Hiche) | C24: 95 | D24: =C24/2.20462 -> 43.091326 | E24: FOB Qingdao | F24: China | G24: Qingdao | H24: 3203.00.8000 | I24: 0.381 | J24: 3 | K24: 0 | L24: =(C24*(1+I24))+J24 -> 134.195 | M24: =L24/2.20462 -> 60.8699 | O24: =L24/(1-N24) -> 134.195 | P24: =O24/2.2 -> 60.997727
A25: Butterfly pea | B25: Butterfly Pea (Hiche) | C25: 180 | D25: =C25/2.20462 -> 81.646724 | E25: FOB Qingdao | F25: China | G25: Qingdao | H25: 3203.00.8000 | I25: 0.381 | J25: 3 | K25: 0 | L25: =(C25*(1+I25))+J25 -> 251.58 | M25: =L25/2.20462 -> 114.1149 | O25: =L25/(1-N25) -> 251.58 | P25: =O25/2.2 -> 114.35455 | Q25: 300CV
A26: Beet powder 2.1% | B26: Beet Powder 2.1% (Nutracean) | C26: 35 | D26: =C26/2.20462 -> 15.875752 | E26: CIF NY | F26: China | G26: Nutracean | H26: 3203.00.8000 | I26: 0.381 | J26: 3 | K26: 0 | L26: =(C26*(1+I26))+J26 -> 51.335 | M26: =L26/2.20462 -> 23.285192 | O26: =L26/(1-N26) -> 51.335 | P26: =O26/2.2 -> 23.334091
A27: Beet powder .8% | B27: Beet Powder 0.8% (Nutracean) | C27: 11 | D27: =C27/2.20462 -> 4.989522 | E27: FCA Long Beach | F27: China | G27: Nutracean | H27: 3203.00.8000 | I27: 0.381 | J27: 1 | K27: 0 | L27: =(C27*(1+I27))+J27 -> 16.191 | M27: =L27/2.20462 -> 7.3441228 | N27: 0.145 | O27: =L27/(1-N27) -> 18.936842 | P27: =O27/2.2 -> 8.6076555
A28: Black Carrot EV100 | B28: Black Carrot EV100 (Nutracean) | C28: 120 | D28: =C28/2.20462 -> 54.431149 | E28: FOB China | F28: China | G28: Nutracean | H28: 3203.00.8000 | I28: 0.381 | J28: 2 | L28: =(C28*(1+I28))+J28 -> 167.72 | M28: =L28/2.20462 -> 76.076603
A29: Beet powder .7% | B29: Natural Red D1307 (Seneca) | C29: 17.23 | D29: =C29/2.20462 -> 7.8154058 | E29: FOB Clyman, WI | F29: US | G29: Seneca | H29: n/a | J29: 0.75 | K29: 0 | L29: =(C29*(1+I29))+J29 -> 17.98 | M29: =L29/2.20462 -> 8.1556005 | N29: 0.14 | O29: =L29/(1-N29) -> 20.906977 | P29: =O29/2.2 -> 9.5031712
A30: Beet powder .5% | B30: Natural Red D1305 (Seneca) | C30: 15.55 | D30: =C30/2.20462 -> 7.0533697 | E30: FOB Clyman, WI | F30: US | G30: Seneca | H30: n/a | J30: 0.75 | K30: 0 | L30: =(C30*(1+I30))+J30 -> 16.3 | M30: =L30/2.20462 -> 7.3935644 | N30: 0.2 | O30: =L30/(1-N30) -> 20.375 | P30: =O30/2.2 -> 9.2613636
A31: VeryOx 5% liquid | B31: VeryOx 5% liquid | C31: 21.38 | D31: =C31/2.20462 -> 9.6978164 | E31: EXW Casablanca | F31: Morocco | G31: PhytoProd | H31: 1302.19.9140 | I31: 0.1 | J31: 2 | K31: 0 | L31: =(C31*(1+I31))+J31 -> 25.518 | M31: =L31/2.20462 -> 11.574784 | O31: =L31/(1-N31) -> 25.518 | P31: =O31/2.2 -> 11.599091 | R31: Phytoprod raised prices 8% on 4/14 due to currency exchange rates
A32: VeryOx 5% powder | B32: VeryOx 5% powder | C32: 12.5 | D32: =C32/2.20462 -> 5.6699114 | E32: EXW Casablanca | F32: Morocco | G32: PhytoProd | H32: 1302.19.9140 | I32: 0.1 | J32: 2 | K32: 0 | L32: =(C32*(1+I32))+J32 -> 15.75 | M32: =L32/2.20462 -> 7.1440883 | O32: =L32/(1-N32) -> 15.75 | P32: =O32/2.2 -> 7.1590909
A33: Carnosox 10% liquid | B33: Carnosox 10% liquid | C33: 41.04 | D33: =C33/2.20462 -> 18.615453 | E33: EXW Casablanca | F33: Morocco | G33: PhytoProd | H33: 1302.19.9140 | I33: 0.1 | J33: 2 | K33: 0 | L33: =(C33*(1+I33))+J33 -> 47.144 | M33: =L33/2.20462 -> 21.384184 | N33: 0.3 | O33: =L33/(1-N33) -> 67.348571 | P33: =O33/2.2 -> 30.612987
A34: Carnosox 10% powder | B34: Carnosox 10% powder | C34: 18.36 | D34: =C34/2.20462 -> 8.3279658 | E34: EXW Casablanca | F34: Morocco | G34: PhytoProd | H34: 1302.19.9140 | I34: 0.1 | J34: 2 | K34: 0 | L34: =(C34*(1+I34))+J34 -> 22.196 | M34: =L34/2.20462 -> 10.067948 | O34: =L34/(1-N34) -> 22.196 | P34: =O34/2.2 -> 10.089091
A35: Carnosox PP (High vol price) | B35: Carnosox PP | C35: 13.64 | D35: =C35/2.20462 -> 6.1870073 | E35: CIF Chicago | F35: Morocco | G35: PhytoProd | H35: 1302.19.9140 | I35: 0.1 | J35: 2 | K35: 0 | L35: =(C35*(1+I35))+J35 -> 17.004 | M35: =L35/2.20462 -> 7.7128938 | N35: 0.4 | O35: =L35/(1-N35) -> 28.34 | P35: =O35/2.2 -> 12.881818 | T35: Can go to 14.87/kg for large volume
A36: Carnosic 5% liquid | B36: Carnosic 5% liquid | C36: 15 | D36: =C36/2.20462 -> 6.8038936 | E36: FOB Qingdao | F36: China | G36: Qingdao | H36: 1302.19.9140 | I36: 0.62 | J36: 2 | K36: 0 | L36: =(C36*(1+I36))+J36 -> 26.3 | M36: =L36/2.20462 -> 11.929494 | O36: =L36/(1-N36) -> 26.3 | P36: =O36/2.2 -> 11.954545
A37: Carnosic 15% pwd | B37: Carnosic 15% pwd | C37: 25 | D37: =C37/2.20462 -> 11.339823 | E37: FOB Qingdao | F37: China | G37: Qingdao | H37: 1302.19.9140 | I37: 0.62 | J37: 2 | K37: 0 | L37: =(C37*(1+I37))+J37 -> 42.5 | M37: =L37/2.20462 -> 19.277699 | N37: 0.3 | O37: =L37/(1-N37) -> 60.714286 | P37: =O37/2.2 -> 27.597403
A38: Carnosic 10% liquid | B38: Carnosic 10% liquid | C38: 29 | D38: =C38/2.20462 -> 13.154194 | E38: FOB Qingdao | F38: China | G38: Qingdao | H38: 1302.19.9140 | I38: 0.62 | J38: 2 | K38: 0 | L38: =(C38*(1+I38))+J38 -> 48.98 | M38: =L38/2.20462 -> 22.216981 | O38: =L38/(1-N38) -> 48.98 | P38: =O38/2.2 -> 22.263636
A39: Carnosic 20% pwd | B39: Carnosic 20% pwd | C39: 32 | D39: =C39/2.20462 -> 14.514973 | E39: FOB Qingdao | F39: China | G39: Qingdao | H39: 1302.19.9140 | I39: 0.62 | J39: 2 | K39: 0 | L39: =(C39*(1+I39))+J39 -> 53.84 | M39: =L39/2.20462 -> 24.421442 | O39: =L39/(1-N39) -> 53.84 | P39: =O39/2.2 -> 24.472727
A40: NaCu Chlorophyll 98% | B40: NaCu Chlorophyll 98% (Nutracean) | C40: 180 | D40: =C40/2.20462 -> 81.646724 | E40: FOB China | F40: China | G40: Nutracean | H40: 3203.00.8000 | I40: 0.48 | J40: 3 | K40: 0 | L40: =(C40*(1+I40))+J40 -> 269.4 | M40: =L40/2.20462 -> 122.19793 | O40: =L40/(1-N40) -> 269.4 | P40: =O40/2.2 -> 122.45455 | Q40: 0.98
...

Sheet Manufactured Items Models
A1: Annatto | G1: Beet | M1: Butterfly Pea | S1: Purple Sweet Potato | Y1: Radish | AE1: Spirulina | AK1: Black Carrot | AQ1: Red Cabbage | AW1: Beta Carotene
A2: 8 | B2: Annatto Extract P2401 | C2: Composition | D2: Price/lb | E2: Formula Cost | G2: 40 | H2: Natural Red D1303 | I2: Composition | J2: Price/lb | K2: Formula Cost | M2: 11 | N2: Natural BP N1399 | O2: Composition | P2: Price/lb | Q2: Formula Cost | S2: 44 | T2: Natural Red A1320 | U2: Composition | V2: Price/lb | W2: Formula Cost | Y2: 44 | Z2: Natural Red E1430 | AA2: Composition | AB2: Price/lb | AC2: Formula Cost | AE2: 11 | AF2: Natural Blue L1355 | AG2: Composition | AH2: Price/lb | AI2: Formula Cost | AK2: 8 | AL2: Natural Red C1409 | AM2: Composition | AN2: Price/lb | AO2: Formula Cost | AQ2: 8 | AR2: Natural Red B1416 | AS2: Composition | AT2: Price/lb | AU2: Formula Cost | AW2: 44 | AX2: Natural Yellow G3401-N | AY2: Composition | AZ2: Price/lb | BA2: Formula Cost
A3: R1 | B3: Annatto Extract P2404 (Cyber Colors) | C3: 0.05 | D3: =IFERROR(VLOOKUP(B3,'Cost Master List'!$B$2:$P$74,12,),0) -> 7.3221235 | E3: =+D3*C3 -> 0.36610618 | G3: R1 | H3: Beet Powder 0.8% (Nutracean) | I3: 0.375 | J3: =IFERROR(VLOOKUP(H3,'Cost Master List'!$B$2:$P$74,12,),0) -> 7.3441228 | K3: =+J3*I3 -> 2.754046 | M3: R1 | N3: Butterfly Pea (Hiche) | O3: 0.33 | P3: =IFERROR(VLOOKUP(N3,'Cost Master List'!$B$2:$P$74,12,),0) -> 114.1149 | Q3: =+P3*O3 -> 37.657918 | S3: R1 | T3: Purple Sweet Potato (Hiche) | U3: 0.25 | V3: =IFERROR(VLOOKUP(T3,'Cost Master List'!$B$2:$P$74,12,),0) -> 60.8699 | W3: =+V3*U3 -> 15.217475 | Y3: R1 | Z3: Red Radish EV50 (Nutracean) | AA3: 0.06 | AB3: =IFERROR(VLOOKUP(Z3,'Cost Master List'!$B$2:$P$74,12,),0) -> 51.02013 | AC3: =+AB3*AA3 -> 3.0612078 | AE3: R1 | AF3: Natural Blue L1300 (Hiche) | AG3: 0.317 | AH3: =IFERROR(VLOOKUP(AF3,'Cost Master List'!$B$2:$P$74,12,),0) -> 51.473723 | AI3: =+AH3*AG3 -> 16.31717 | AK3: R1 | AL3: VJfC Bcarrot/BIB (Dohler) | AM3: 0.275 | AN3: =IFERROR(VLOOKUP(AL3,'Cost Master List'!$B$2:$P$74,12,),0) -> 20.815229 | AO3: =+AN3*AM3 -> 5.724188 | AQ3: R1 | AR3: Red Cabbage E60 (Nutracean) | AS3: 0.243 | AT3: =IFERROR(VLOOKUP(AR3,'Cost Master List'!$B$2:$P$74,12,),0) -> 81.54149 | AU3: =+AT3*AS3 -> 19.814582 | AW3: R1 | AX3: Natural Yellow G3403 (Cybercolors) | AY3: 0.215 | AZ3: =IFERROR(VLOOKUP(AX3,'Cost Master List'!$B$2:$P$74,12,),0) -> 15.404501 | BA3: =+AZ3*AY3 -> 3.3119676
A4: R2 | B4: Sun Flower Oil* | C4: 0.95 | D4: =IFERROR(VLOOKUP(B4,'Cost Master List'!$B$2:$P$74,12,),0) -> 1.1850115 | E4: =+D4*C4 -> 1.1257609 | G4: R2 | H4: Maltodextrin M-100 IP (Brenntag) | I4: 0.63 | J4: =IFERROR(VLOOKUP(H4,'Cost Master List'!$B$2:$P$74,12,),0) -> 0.83914688 | K4: =+J4*I4 -> 0.52866254 | M4: R2 | N4: Maltodextrin M-100 IP (Brenntag) | O4: 0.67 | P4: =IFERROR(VLOOKUP(N4,'Cost Master List'!$B$2:$P$74,12,),0) -> 0.83914688 | Q4: =+P4*O4 -> 0.56222841 | S4: R2 | T4: Maltodextrin M-100 IP (Brenntag) | U4: 0.75 | V4: =IFERROR(VLOOKUP(T4,'Cost Master List'!$B$2:$P$74,12,),0) -> 0.83914688 | W4: =+V4*U4 -> 0.62936016 | Y4: R2 | Z4: Citric Acid* | AA4: 0.005 | AB4: =IFERROR(VLOOKUP(Z4,'Cost Master List'!$B$2:$P$74,12,),0) -> 4.5359291 | AC4: =+AB4*AA4 -> 0.022679645 | AE4: R2 | AF4: Maltodextrin M-100 IP (Brenntag) | AG4: 0.683 | AH4: =IFERROR(VLOOKUP(AF4,'Cost Master List'!$B$2:$P$74,12,),0) -> 0.83914688 | AI4: =+AH4*AG4 -> 0.57313732 | AK4: R2 | AL4: DI Water | AM4: 0.1008 | AN4: =IFERROR(VLOOKUP(AL4,'Cost Master List'!$B$2:$P$74,12,),0) -> 0.22679645 | AO4: =+AN4*AM4 -> 0.022861083 | AQ4: R2 | AR4: Propelyene Glycol* | AS4: 0.2 | AT4: =IFERROR(VLOOKUP(AR4,'Cost Master List'!$B$2:$P$74,12,),0) -> 4.5359291 | AU4: =+AT4*AS4 -> 0.90718582 | AW4: R2 | AX4: DI Water | AY4: 0.771 | AZ4: =IFERROR(VLOOKUP(AX4,'Cost Master List'!$B$2:$P$74,12,),0) -> 0.22679645 | BA4: =+AZ4*AY4 -> 0.17486007
A5: R3 | D5: =IFERROR(VLOOKUP(B5,'Cost Master List'!$B$2:$P$74,12,),0) -> 0 | E5: =+D5*C5 -> 0 | G5: R3 | J5: =IFERROR(VLOOKUP(H5,'Cost Master List'!$B$2:$P$74,12,),0) -> 0 | K5: =+J5*I5 -> 0 | M5: R3 | P5: =IFERROR(VLOOKUP(N5,'Cost Master List'!$B$2:$P$74,12,),0) -> 0 | Q5: =+P5*O5 -> 0 | S5: R3 | V5: =IFERROR(VLOOKUP(T5,'Cost Master List'!$B$2:$P$74,12,),0) -> 0 | W5: =+V5*U5 -> 0 | Y5: R3 | Z5: Propelyene Glycol* | AA5: 0.2047 | AB5: =IFERROR(VLOOKUP(Z5,'Cost Master List'!$B$2:$P$74,12,),0) -> 4.5359291 | AC5: =+AB5*AA5 -> 0.92850469 | AE5: R3 | AH5: =IFERROR(VLOOKUP(AF5,'Cost Master List'!$B$2:$P$74,12,),0) -> 0 | AI5: =+AH5*AG5 -> 0 | AK5: R3 | AL5: Citric Acid* | AM5: 0.003 | AN5: =IFERROR(VLOOKUP(AL5,'Cost Master List'!$B$2:$P$74,12,),0) -> 4.5359291 | AO5: =+AN5*AM5 -> 0.013607787 | AQ5: R3 | AR5: DI Water | AS5: 0.553 | AT5: =IFERROR(VLOOKUP(AR5,'Cost Master List'!$B$2:$P$74,12,),0) -> 0.22679645 | AU5: =+AT5*AS5 -> 0.12541844 | AW5: R3 | AX5: Potassium Sorbate (Brenntag) | AY5: 0.0013 | AZ5: =IFERROR(VLOOKUP(AX5,'Cost Master List'!$B$2:$P$74,12,),0) -> 2.0184884 | BA5: =+AZ5*AY5 -> 0.002624035
A6: R4 | D6: =IFERROR(VLOOKUP(B6,'Cost Master List'!$B$2:$P$74,12,),0) -> 0 | E6: =+D6*C6 -> 0 | G6: R4 | J6: =IFERROR(VLOOKUP(H6,'Cost Master List'!$B$2:$P$74,12,),0) -> 0 | K6: =+J6*I6 -> 0 | M6: R4 | P6: =IFERROR(VLOOKUP(N6,'Cost Master List'!$B$2:$P$74,12,),0) -> 0 | Q6: =+P6*O6 -> 0 | S6: R4 | V6: =IFERROR(VLOOKUP(T6,'Cost Master List'!$B$2:$P$74,12,),0) -> 0 | W6: =+V6*U6 -> 0 | Y6: R4 | Z6: DI Water | AA6: 0.7303 | AB6: =IFERROR(VLOOKUP(Z6,'Cost Master List'!$B$2:$P$74,12,),0) -> 0.22679645 | AC6: =+AB6*AA6 -> 0.16562945 | AE6: R4 | AH6: =IFERROR(VLOOKUP(AF6,'Cost Master List'!$B$2:$P$74,12,),0) -> 0 | AI6: =+AH6*AG6 -> 0 | AK6: R4 | AL6: Potassium Sorbate (Brenntag) | AM6: 0.002 | AN6: =IFERROR(VLOOKUP(AL6,'Cost Master List'!$B$2:$P$74,12,),0) -> 2.0184884 | AO6: =+AN6*AM6 -> 0.0040369769 | AQ6: R4 | AR6: Citric Acid* | AS6: 0.004 | AT6: =IFERROR(VLOOKUP(AR6,'Cost Master List'!$B$2:$P$74,12,),0) -> 4.5359291 | AU6: =+AT6*AS6 -> 0.018143716 | AW6: R4 | AX6: Ascorbic Acid (Brenntag) | AY6: 0.01 | AZ6: =IFERROR(VLOOKUP(AX6,'Cost Master List'!$B$2:$P$74,12,),0) -> 1.8052998 | BA6: =+AZ6*AY6 -> 0.018052998
A7: R5 | D7: =IFERROR(VLOOKUP(B7,'Cost Master List'!$B$2:$P$74,12,),0) -> 0 | E7: =+D7*C7 -> 0 | G7: R5 | J7: =IFERROR(VLOOKUP(H7,'Cost Master List'!$B$2:$P$74,12,),0) -> 0 | K7: =+J7*I7 -> 0 | M7: R5 | P7: =IFERROR(VLOOKUP(N7,'Cost Master List'!$B$2:$P$74,12,),0) -> 0 | Q7: =+P7*O7 -> 0 | S7: R5 | V7: =IFERROR(VLOOKUP(T7,'Cost Master List'!$B$2:$P$74,12,),0) -> 0 | W7: =+V7*U7 -> 0 | Y7: R5 | AB7: =IFERROR(VLOOKUP(Z7,'Cost Master List'!$B$2:$P$74,12,),0) -> 0 | AC7: =+AB7*AA7 -> 0 | AE7: R5 | AH7: =IFERROR(VLOOKUP(AF7,'Cost Master List'!$B$2:$P$74,12,),0) -> 0 | AI7: =+AH7*AG7 -> 0 | AK7: R5 | AL7: Sorbitol* | AM7: 0.6192 | AN7: =IFERROR(VLOOKUP(AL7,'Cost Master List'!$B$2:$P$74,12,),0) -> 1.8143716 | AO7: =+AN7*AM7 -> 1.1234589 | AQ7: R5 | AT7: =IFERROR(VLOOKUP(AR7,'Cost Master List'!$B$2:$P$74,12,),0) -> 0 | AU7: =+AT7*AS7 -> 0 | AW7: R5 | AZ7: =IFERROR(VLOOKUP(AX7,'Cost Master List'!$B$2:$P$74,12,),0) -> 0 | BA7: =+AZ7*AY7 -> 0
A8: P1 | B8: 1 Gallon Jug & Box Combo | D8: =IFERROR(VLOOKUP('Manufactured Items Models'!B8,'Cost Master List'!$B$84:$L$98,11,FALSE),0) -> 1.6 | E8: =+D8/$A$2 -> 0.2 | G8: P1 | H8: 15x15x15 box | J8: =IFERROR(VLOOKUP('Manufactured Items Models'!H8,'Cost Master List'!$B$84:$L$98,11,FALSE),0) -> 2.47 | K8: =+J8/$G$2 -> 0.06175 | M8: P1 | N8: 16x12x10 box | P8: =IFERROR(VLOOKUP('Manufactured Items Models'!N8,'Cost Master List'!$B$84:$L$98,11,FALSE),0) -> 1.92 | Q8: =+P8/$M$2 -> 0.17454545 | S8: P1 | T8: 15x15x15 box | V8: =IFERROR(VLOOKUP('Manufactured Items Models'!T8,'Cost Master List'!$B$84:$L$98,11,FALSE),0) -> 2.47 | W8: =+V8/$S$2 -> 0.056136364 | Y8: P1 | Z8: 5 Gallon Pails | AB8: =IFERROR(VLOOKUP('Manufactured Items Models'!Z8,'Cost Master List'!$B$84:$L$98,11,FALSE),0) -> 9.68 | AC8: =+AB8/$Y$2 -> 0.22 | AE8: P1 | AF8: 16x12x10 box | AH8: =IFERROR(VLOOKUP('Manufactured Items Models'!AF8,'Cost Master List'!$B$84:$L$98,11,FALSE),0) -> 1.92 | AI8: =+AH8/$AE$2 -> 0.17454545 | AK8: P1 | AL8: 5 Gallon Pails | AN8: =IFERROR(VLOOKUP('Manufactured Items Models'!AL8,'Cost Master List'!$B$84:$L$98,11,FALSE),0) -> 9.68 | AO8: =+AN8/$G$14 -> 0.242 | AQ8: P1 | AR8: 1 Gallon Jug & Box Combo | AT8: =IFERROR(VLOOKUP('Manufactured Items Models'!AR8,'Cost Master List'!$B$84:$L$98,11,FALSE),0) -> 1.6 | AU8: =+AT8/$G$14 -> 0.04 | AW8: P1 | AX8: 5 Gallon Pails | AZ8: =IFERROR(VLOOKUP('Manufactured Items Models'!AX8,'Cost Master List'!$B$84:$L$98,11,FALSE),0) -> 9.68 | BA8: =+AZ8/$G$14 -> 0.242
A9: P2 | D9: =IFERROR(VLOOKUP('Manufactured Items Models'!B9,'Cost Master List'!$B$84:$L$98,11,FALSE),0) -> 0 | E9: =+D9/$A$2 -> 0 | G9: P2 | H9: Blue USFDA Poly Bag 34x40x.004 | J9: =IFERROR(VLOOKUP('Manufactured Items Models'!H9,'Cost Master List'!$B$84:$L$98,11,FALSE),0) -> 0.678 | K9: =+J9/$G$2 -> 0.01695 | M9: P2 | N9: Blue USFDA Poly Bag 32x32x.004 | P9: =IFERROR(VLOOKUP('Manufactured Items Models'!N9,'Cost Master List'!$B$84:$L$98,11,FALSE),0) -> 0.553 | Q9: =+P9/$M$2 -> 0.050272727 | S9: P2 | T9: Blue USFDA Poly Bag 34x40x.004 | V9: =IFERROR(VLOOKUP('Manufactured Items Models'!T9,'Cost Master List'!$B$84:$L$98,11,FALSE),0) -> 0.678 | W9: =+V9/$S$2 -> 0.015409091 | Y9: P2 | AB9: =IFERROR(VLOOKUP('Manufactured Items Models'!Z9,'Cost Master List'!$B$84:$L$98,11,FALSE),0) -> 0 | AC9: =+AB9/$Y$2 -> 0 | AE9: P2 | AF9: Blue USFDA Poly Bag 32x32x.004 | AH9: =IFERROR(VLOOKUP('Manufactured Items Models'!AF9,'Cost Master List'!$B$84:$L$98,11,FALSE),0) -> 0.553 | AI9: =+AH9/$AE$2 -> 0.050272727 | AK9: P2 | AN9: =IFERROR(VLOOKUP('Manufactured Items Models'!AL9,'Cost Master List'!$B$84:$L$98,11,FALSE),0) -> 0 | AO9: =+AN9/$G$14 -> 0 | AQ9: P2 | AT9: =IFERROR(VLOOKUP('Manufactured Items Models'!AR9,'Cost Master List'!$B$84:$L$98,11,FALSE),0) -> 0 | AU9: =+AT9/$G$14 -> 0 | AW9: P2 | AZ9: =IFERROR(VLOOKUP('Manufactured Items Models'!AX9,'Cost Master List'!$B$84:$L$98,11,FALSE),0) -> 0 | BA9: =+AZ9/$G$14 -> 0
A10: P3 | D10: =IFERROR(VLOOKUP('Manufactured Items Models'!B10,'Cost Master List'!$B$84:$L$98,11,FALSE),0) -> 0 | E10: =+D10/$A$2 -> 0 | G10: P3 | J10: =IFERROR(VLOOKUP('Manufactured Items Models'!H10,'Cost Master List'!$B$84:$L$98,11,FALSE),0) -> 0 | K10: =+J10/$G$2 -> 0 | M10: P3 | P10: =IFERROR(VLOOKUP('Manufactured Items Models'!N10,'Cost Master List'!$B$84:$L$98,11,FALSE),0) -> 0 | Q10: =+P10/$M$2 -> 0 | S10: P3 | V10: =IFERROR(VLOOKUP('Manufactured Items Models'!T10,'Cost Master List'!$B$84:$L$98,11,FALSE),0) -> 0 | W10: =+V10/$S$2 -> 0 | Y10: P3 | AB10: =IFERROR(VLOOKUP('Manufactured Items Models'!Z10,'Cost Master List'!$B$84:$L$98,11,FALSE),0) -> 0 | AC10: =+AB10/$Y$2 -> 0 | AE10: P3 | AH10: =IFERROR(VLOOKUP('Manufactured Items Models'!AF10,'Cost Master List'!$B$84:$L$98,11,FALSE),0) -> 0 | AI10: =+AH10/$AE$2 -> 0 | AK10: P3 | AN10: =IFERROR(VLOOKUP('Manufactured Items Models'!AL10,'Cost Master List'!$B$84:$L$98,11,FALSE),0) -> 0 | AO10: =+AN10/$G$14 -> 0 | AQ10: P3 | AT10: =IFERROR(VLOOKUP('Manufactured Items Models'!AR10,'Cost Master List'!$B$84:$L$98,11,FALSE),0) -> 0 | AU10: =+AT10/$G$14 -> 0 | AW10: P3 | AZ10: =IFERROR(VLOOKUP('Manufactured Items Models'!AX10,'Cost Master List'!$B$84:$L$98,11,FALSE),0) -> 0 | BA10: =+AZ10/$G$14 -> 0
A11: Labor | E11: 0.25 | G11: Labor | K11: 1 | M11: Labor | Q11: 1 | S11: Labor | W11: 1 | Y11: Labor | AC11: 1 | AE11: Labor | AI11: 1 | AK11: Labor | AO11: 1 | AQ11: Labor | AU11: 1 | AW11: Labor | BA11: 1
B12: Annatto Extract P2401 (8) | D12: Cost/lb | E12: =+SUM(E3:E11) -> 1.9418671 | H12: Natural Red D1303 (40) | J12: Cost/lb | K12: =+SUM(K3:K11) -> 4.3614086 | N12: Natural BP N1399 (11) | P12: Cost/lb | Q12: =+SUM(Q3:Q11) -> 39.444965 | T12: Natural Red A1320 (44) | V12: Cost/lb | W12: =+SUM(W3:W11) -> 16.918381 | Z12: Natural Red E1430 (44) | AB12: Cost/lb | AC12: =+SUM(AC3:AC11) -> 5.3980216 | AF12: Natural Blue L1355 (11) | AH12: Cost/lb | AI12: =+SUM(AI3:AI11) -> 18.115126 | AL12: Natural Red C1409 (8) | AN12: Cost/lb | AO12: =+SUM(AO3:AO11) -> 8.1301527 | AR12: Natural Red B1416 (8) | AT12: Cost/lb | AU12: =+SUM(AU3:AU11) -> 21.90533 | AX12: Natural Yellow G3401-N (44) | AZ12: Cost/lb | BA12: =+SUM(BA3:BA11) -> 4.7495047
A14: 40 | B14: Annatto Extract P2401 | C14: Composition | D14: Price/lb | E14: Formula Cost | G14: 40 | H14: Natural Red D1305 | I14: Composition | J14: Price/lb | K14: Formula Cost | O14: Composition | P14: Price/lb | Q14: Formula Cost | U14: Composition | V14: Price/lb | W14: Formula Cost | AA14: Composition | AB14: Price/lb | AC14: Formula Cost | AE14: 44 | AF14: Natural Blue L1405 | AG14: Composition | AH14: Price/lb | AI14: Formula Cost | AK14: 44 | AL14: Natural Red C1309 | AM14: Composition | AN14: Price/lb | AO14: Formula Cost | AS14: Composition | AT14: Price/lb | AU14: Formula Cost | AY14: Composition | AZ14: Price/lb | BA14: Formula Cost
A15: R1 | B15: Annatto Extract P2404 (Cyber Colors) | C15: 0.05 | D15: =IFERROR(VLOOKUP(B15,'Cost Master List'!$B$2:$P$74,12,),0) -> 7.3221235 | E15: =+D15*C15 -> 0.36610618 | G15: R1 | H15: Beet Powder 0.8% (Nutracean) | I15: 0.625 | J15: =IFERROR(VLOOKUP(H15,'Cost Master List'!$B$2:$P$74,12,),0) -> 7.3441228 | K15: =+J15*I15 -> 4.5900767 | M15: R1 | P15: =IFERROR(VLOOKUP(N15,'Cost Master List'!$B$2:$P$74,12,),0) -> 0 | Q15: =+P15*O15 -> 0 | S15: R1 | V15: =IFERROR(VLOOKUP(T15,'Cost Master List'!$B$2:$P$74,12,),0) -> 0 | W15: =+V15*U15 -> 0 | Y15: R1 | AB15: =IFERROR(VLOOKUP(Z15,'Cost Master List'!$B$2:$P$74,12,),0) -> 0 | AC15: =+AB15*AA15 -> 0 | AE15: R1 | AF15: Natural Blue L1300 (Hiche) | AG15: 0.25 | AH15: =IFERROR(VLOOKUP(AF15,'Cost Master List'!$B$2:$P$74,12,),0) -> 51.473723 | AI15: =+AH15*AG15 -> 12.868431 | AK15: R1 | AL15: Not Assigned | AM15: 0.3 | AN15: =IFERROR(VLOOKUP(AL15,'Cost Master List'!$B$2:$P$74,12,),0) -> 5.9091816 | AO15: =+AN15*AM15 -> 1.7727545 | AQ15: R1 | AT15: =IFERROR(VLOOKUP(AR15,'Cost Master List'!$B$2:$P$74,12,),0) -> 0 | AU15: =+AT15*AS15 -> 0 | AW15: R1 | AZ15: =IFERROR(VLOOKUP(AX15,'Cost Master List'!$B$2:$P$74,12,),0) -> 0 | BA15: =+AZ15*AY15 -> 0
A16: R2 | B16: Sun Flower Oil* | C16: 0.95 | D16: =IFERROR(VLOOKUP(B16,'Cost Master List'!$B$2:$P$74,12,),0) -> 1.1850115 | E16: =+D16*C16 -> 1.1257609 | G16: R2 | H16: Maltodextrin M-100 IP (Brenntag) | I16: 0.375 | J16: =IFERROR(VLOOKUP(H16,'Cost Master List'!$B$2:$P$74,12,),0) -> 0.83914688 | K16: =+J16*I16 -> 0.31468008 | M16: R2 | P16: =IFERROR(VLOOKUP(N16,'Cost Master List'!$B$2:$P$74,12,),0) -> 0 | Q16: =+P16*O16 -> 0 | S16: R2 | V16: =IFERROR(VLOOKUP(T16,'Cost Master List'!$B$2:$P$74,12,),0) -> 0 | W16: =+V16*U16 -> 0 | Y16: R2 | AB16: =IFERROR(VLOOKUP(Z16,'Cost Master List'!$B$2:$P$74,12,),0) -> 0 | AC16: =+AB16*AA16 -> 0 | AE16: R2 | AF16: Glycerin* | AG16: 0.55 | AH16: =IFERROR(VLOOKUP(AF16,'Cost Master List'!$B$2:$P$74,12,),0) -> 4.5359291 | AI16: =+AH16*AG16 -> 2.494761 | AK16: R2 | AL16: Maltodextrin M-100 IP (Brenntag) | AM16: 0.7 | AN16: =IFERROR(VLOOKUP(AL16,'Cost Master List'!$B$2:$P$74,12,),0) -> 0.83914688 | AO16: =+AN16*AM16 -> 0.58740282 | AQ16: R2 | AT16: =IFERROR(VLOOKUP(AR16,'Cost Master List'!$B$2:$P$74,12,),0) -> 0 | AU16: =+AT16*AS16 -> 0 | AW16: R2 | AZ16: =IFERROR(VLOOKUP(AX16,'Cost Master List'!$B$2:$P$74,12,),0) -> 0 | BA16: =+AZ16*AY16 -> 0
A17: R3 | D17: =IFERROR(VLOOKUP(B17,'Cost Master List'!$B$2:$P$74,12,),0) -> 0 | E17: =+D17*C17 -> 0 | G17: R3 | J17: =IFERROR(VLOOKUP(H17,'Cost Master List'!$B$2:$P$74,12,),0) -> 0 | K17: =+J17*I17 -> 0 | M17: R3 | P17: =IFERROR(VLOOKUP(N17,'Cost Master List'!$B$2:$P$74,12,),0) -> 0 | Q17: =+P17*O17 -> 0 | S17: R3 | V17: =IFERROR(VLOOKUP(T17,'Cost Master List'!$B$2:$P$74,12,),0) -> 0 | W17: =+V17*U17 -> 0 | Y17: R3 | AB17: =IFERROR(VLOOKUP(Z17,'Cost Master List'!$B$2:$P$74,12,),0) -> 0 | AC17: =+AB17*AA17 -> 0 | AE17: R3 | AF17: DI Water | AG17: 0.2 | AH17: =IFERROR(VLOOKUP(AF17,'Cost Master List'!$B$2:$P$74,12,),0) -> 0.22679645 | AI17: =+AH17*AG17 -> 0.045359291 | AK17: R3 | AN17: =IFERROR(VLOOKUP(AL17,'Cost Master List'!$B$2:$P$74,12,),0) -> 0 | AO17: =+AN17*AM17 -> 0 | AQ17: R3 | AT17: =IFERROR(VLOOKUP(AR17,'Cost Master List'!$B$2:$P$74,12,),0) -> 0 | AU17: =+AT17*AS17 -> 0 | AW17: R3 | AZ17: =IFERROR(VLOOKUP(AX17,'Cost Master List'!$B$2:$P$74,12,),0) -> 0 | BA17: =+AZ17*AY17 -> 0
A18: R4 | D18: =IFERROR(VLOOKUP(B18,'Cost Master List'!$B$2:$P$74,12,),0) -> 0 | E18: =+D18*C18 -> 0 | G18: R4 | J18: =IFERROR(VLOOKUP(H18,'Cost Master List'!$B$2:$P$74,12,),0) -> 0 | K18: =+J18*I18 -> 0 | M18: R4 | P18: =IFERROR(VLOOKUP(N18,'Cost Master List'!$B$2:$P$74,12,),0) -> 0 | Q18: =+P18*O18 -> 0 | S18: R4 | V18: =IFERROR(VLOOKUP(T18,'Cost Master List'!$B$2:$P$74,12,),0) -> 0 | W18: =+V18*U18 -> 0 | Y18: R4 | AB18: =IFERROR(VLOOKUP(Z18,'Cost Master List'!$B$2:$P$74,12,),0) -> 0 | AC18: =+AB18*AA18 -> 0 | AE18: R4 | AH18: =IFERROR(VLOOKUP(AF18,'Cost Master List'!$B$2:$P$74,12,),0) -> 0 | AI18: =+AH18*AG18 -> 0 | AK18: R4 | AN18: =IFERROR(VLOOKUP(AL18,'Cost Master List'!$B$2:$P$74,12,),0) -> 0 | AO18: =+AN18*AM18 -> 0 | AQ18: R4 | AT18: =IFERROR(VLOOKUP(AR18,'Cost Master List'!$B$2:$P$74,12,),0) -> 0 | AU18: =+AT18*AS18 -> 0 | AW18: R4 | AZ18: =IFERROR(VLOOKUP(AX18,'Cost Master List'!$B$2:$P$74,12,),0) -> 0 | BA18: =+AZ18*AY18 -> 0
A19: R5 | D19: =IFERROR(VLOOKUP(B19,'Cost Master List'!$B$2:$P$74,12,),0) -> 0 | E19: =+D19*C19 -> 0 | G19: R5 | J19: =IFERROR(VLOOKUP(H19,'Cost Master List'!$B$2:$P$74,12,),0) -> 0 | K19: =+J19*I19 -> 0 | M19: R5 | P19: =IFERROR(VLOOKUP(N19,'Cost Master List'!$B$2:$P$74,12,),0) -> 0 | Q19: =+P19*O19 -> 0 | S19: R5 | V19: =IFERROR(VLOOKUP(T19,'Cost Master List'!$B$2:$P$74,12,),0) -> 0 | W19: =+V19*U19 -> 0 | Y19: R5 | AB19: =IFERROR(VLOOKUP(Z19,'Cost Master List'!$B$2:$P$74,12,),0) -> 0 | AC19: =+AB19*AA19 -> 0 | AE19: R5 | AH19: =IFERROR(VLOOKUP(AF19,'Cost Master List'!$B$2:$P$74,12,),0) -> 0 | AI19: =+AH19*AG19 -> 0 | AK19: R5 | AN19: =IFERROR(VLOOKUP(AL19,'Cost Master List'!$B$2:$P$74,12,),0) -> 0 | AO19: =+AN19*AM19 -> 0 | AQ19: R5 | AT19: =IFERROR(VLOOKUP(AR19,'Cost Master List'!$B$2:$P$74,12,),0) -> 0 | AU19: =+AT19*AS19 -> 0 | AW19: R5 | AZ19: =IFERROR(VLOOKUP(AX19,'Cost Master List'!$B$2:$P$74,12,),0) -> 0 | BA19: =+AZ19*AY19 -> 0
A20: P1 | B20: 5 Gallon Pails | D20: =IFERROR(VLOOKUP('Manufactured Items Models'!B20,'Cost Master List'!$B$84:$L$98,11,FALSE),0) -> 9.68 | E20: =+D20/$A$14 -> 0.242 | G20: P1 | H20: 15x15x15 box | J20: =IFERROR(VLOOKUP('Manufactured Items Models'!H20,'Cost Master List'!$B$84:$L$98,11,FALSE),0) -> 2.47 | K20: =+J20/$G$14 -> 0.06175 | M20: P1 | P20: =IFERROR(VLOOKUP('Manufactured Items Models'!N20,'Cost Master List'!$B$84:$L$98,11,FALSE),0) -> 0 | Q20: =+P20/$G$14 -> 0 | S20: P1 | V20: =IFERROR(VLOOKUP('Manufactured Items Models'!T20,'Cost Master List'!$B$84:$L$98,11,FALSE),0) -> 0 | W20: =+V20/$G$14 -> 0 | Y20: P1 | AB20: =IFERROR(VLOOKUP('Manufactured Items Models'!Z20,'Cost Master List'!$B$84:$L$98,11,FALSE),0) -> 0 | AC20: =+AB20/$G$14 -> 0 | AE20: P1 | AF20: 5 Gallon Pails | AH20: =IFERROR(VLOOKUP('Manufactured Items Models'!AF20,'Cost Master List'!$B$84:$L$98,11,FALSE),0) -> 9.68 | AI20: =+AH20/$AE$14 -> 0.22 | AK20: P1 | AL20: 16x12x10 box | AN20: =IFERROR(VLOOKUP('Manufactured Items Models'!AL20,'Cost Master List'!$B$84:$L$98,11,FALSE),0) -> 1.92 | AO20: =+AN20/$G$14 -> 0.048 | AQ20: P1 | AT20: =IFERROR(VLOOKUP('Manufactured Items Models'!AR20,'Cost Master List'!$B$84:$L$98,11,FALSE),0) -> 0 | AU20: =+AT20/$G$14 -> 0 | AW20: P1 | AZ20: =IFERROR(VLOOKUP('Manufactured Items Models'!AX20,'Cost Master List'!$B$84:$L$98,11,FALSE),0) -> 0 | BA20: =+AZ20/$G$14 -> 0
A21: P2 | D21: =IFERROR(VLOOKUP('Manufactured Items Models'!B21,'Cost Master List'!$B$84:$L$98,11,FALSE),0) -> 0 | E21: =+D21/$A$14 -> 0 | G21: P2 | H21: Blue USFDA Poly Bag 34x40x.004 | J21: =IFERROR(VLOOKUP('Manufactured Items Models'!H21,'Cost Master List'!$B$84:$L$98,11,FALSE),0) -> 0.678 | K21: =+J21/$G$14 -> 0.01695 | M21: P2 | P21: =IFERROR(VLOOKUP('Manufactured Items Models'!N21,'Cost Master List'!$B$84:$L$98,11,FALSE),0) -> 0 | Q21: =+P21/$G$14 -> 0 | S21: P2 | V21: =IFERROR(VLOOKUP('Manufactured Items Models'!T21,'Cost Master List'!$B$84:$L$98,11,FALSE),0) -> 0 | W21: =+V21/$G$14 -> 0 | Y21: P2 | AB21: =IFERROR(VLOOKUP('Manufactured Items Models'!Z21,'Cost Master List'!$B$84:$L$98,11,FALSE),0) -> 0 | AC21: =+AB21/$G$14 -> 0 | AE21: P2 | AH21: =IFERROR(VLOOKUP('Manufactured Items Models'!AF21,'Cost Master List'!$B$84:$L$98,11,FALSE),0) -> 0 | AI21: =+AH21/$AE$14 -> 0 | AK21: P2 | AL21: Blue USFDA Poly Bag 32x32x.004 | AN21: =IFERROR(VLOOKUP('Manufactured Items Models'!AL21,'Cost Master List'!$B$84:$L$98,11,FALSE),0) -> 0.553 | AO21: =+AN21/$G$14 -> 0.013825 | AQ21: P2 | AT21: =IFERROR(VLOOKUP('Manufactured Items Models'!AR21,'Cost Master List'!$B$84:$L$98,11,FALSE),0) -> 0 | AU21: =+AT21/$G$14 -> 0 | AW21: P2 | AZ21: =IFERROR(VLOOKUP('Manufactured Items Models'!AX21,'Cost Master List'!$B$84:$L$98,11,FALSE),0) -> 0 | BA21: =+AZ21/$G$14 -> 0
A22: P3 | D22: =IFERROR(VLOOKUP('Manufactured Items Models'!B22,'Cost Master List'!$B$84:$L$98,11,FALSE),0) -> 0 | E22: =+D22/$A$14 -> 0 | G22: P3 | J22: =IFERROR(VLOOKUP('Manufactured Items Models'!H22,'Cost Master List'!$B$84:$L$98,11,FALSE),0) -> 0 | K22: =+J22/$G$14 -> 0 | M22: P3 | P22: =IFERROR(VLOOKUP('Manufactured Items Models'!N22,'Cost Master List'!$B$84:$L$98,11,FALSE),0) -> 0 | Q22: =+P22/$G$14 -> 0 | S22: P3 | V22: =IFERROR(VLOOKUP('Manufactured Items Models'!T22,'Cost Master List'!$B$84:$L$98,11,FALSE),0) -> 0 | W22: =+V22/$G$14 -> 0 | Y22: P3 | AB22: =IFERROR(VLOOKUP('Manufactured Items Models'!Z22,'Cost Master List'!$B$84:$L$98,11,FALSE),0) -> 0 | AC22: =+AB22/$G$14 -> 0 | AE22: P3 | AH22: =IFERROR(VLOOKUP('Manufactured Items Models'!AF22,'Cost Master List'!$B$84:$L$98,11,FALSE),0) -> 0 | AI22: =+AH22/$AE$14 -> 0 | AK22: P3 | AN22: =IFERROR(VLOOKUP('Manufactured Items Models'!AL22,'Cost Master List'!$B$84:$L$98,11,FALSE),0) -> 0 | AO22: =+AN22/$G$14 -> 0 | AQ22: P3 | AT22: =IFERROR(VLOOKUP('Manufactured Items Models'!AR22,'Cost Master List'!$B$84:$L$98,11,FALSE),0) -> 0 | AU22: =+AT22/$G$14 -> 0 | AW22: P3 | AZ22: =IFERROR(VLOOKUP('Manufactured Items Models'!AX22,'Cost Master List'!$B$84:$L$98,11,FALSE),0) -> 0 | BA22: =+AZ22/$G$14 -> 0
A23: Labor | E23: 0.25 | G23: Labor | K23: 1 | M23: Labor | Q23: 1 | S23: Labor | W23: 1 | Y23: Labor | AC23: 1 | AE23: Labor | AI23: 1 | AK23: Labor | AO23: 1 | AQ23: Labor | AU23: 1 | AW23: Labor | BA23: 1
B24: Annatto Extract P2401 (40) | D24: Cost/lb | E24: =+SUM(E15:E23) -> 1.9838671 | H24: Natural Red D1305 (40) | J24: Cost/lb | K24: =+SUM(K15:K23) -> 5.9834568 | P24: Cost/lb | Q24: =+SUM(Q15:Q23) -> 1 | V24: Cost/lb | W24: =+SUM(W15:W23) -> 1 | AB24: Cost/lb | AC24: =+SUM(AC15:AC23) -> 1 | AF24: Natural Blue L1405 (44) | AH24: Cost/lb | AI24: =+SUM(AI15:AI23) -> 16.628551 | AL24: Natural Red C1309 (44) | AN24: Cost/lb | AO24: =+SUM(AO15:AO23) -> 3.4219823 | AT24: Cost/lb | AU24: =+SUM(AU15:AU23) -> 1 | AZ24: Cost/lb | BA24: =+SUM(BA15:BA23) -> 1
A26: 40 | B26: Annatto Extract P2404 | C26: Composition | D26: Price/lb | E26: Formula Cost | G26: 40 | H26: Natural Red D1307 | I26: Composition | J26: Price/lb | K26: Formula Cost | O26: Composition | P26: Price/lb | Q26: Formula Cost | U26: Composition | V26: Price/lb | W26: Formula Cost | AA26: Composition | AB26: Price/lb | AC26: Formula Cost | AG26: Composition | AH26: Price/lb | AI26: Formula Cost | AL26: Natural Red C1409 Chen | AM26: Composition | AN26: Price/lb | AO26: Formula Cost | AS26: Composition | AT26: Price/lb | AU26: Formula Cost | AY26: Composition | AZ26: Price/lb | BA26: Formula Cost
A27: R1 | B27: Annatto Extract P2408 (Cyber Colors) | C27: 0.5 | D27: =IFERROR(VLOOKUP(B27,'Cost Master List'!$B$2:$P$74,12,),0) -> 15.542361 | E27: =+D27*C27 -> 7.7711805 | G27: R1 | H27: Beet Powder 0.8% (Nutracean) | I27: 0.875 | J27: =IFERROR(VLOOKUP(H27,'Cost Master List'!$B$2:$P$74,12,),0) -> 7.3441228 | K27: =+J27*I27 -> 6.4261074 | M27: R1 | P27: =IFERROR(VLOOKUP(N27,'Cost Master List'!$B$2:$P$74,12,),0) -> 0 | Q27: =+P27*O27 -> 0 | S27: R1 | V27: =IFERROR(VLOOKUP(T27,'Cost Master List'!$B$2:$P$74,12,),0) -> 0 | W27: =+V27*U27 -> 0 | Y27: R1 | AB27: =IFERROR(VLOOKUP(Z27,'Cost Master List'!$B$2:$P$74,12,),0) -> 0 | AC27: =+AB27*AA27 -> 0 | AE27: R1 | AH27: =IFERROR(VLOOKUP(AF27,'Cost Master List'!$B$2:$P$74,12,),0) -> 0 | AI27: =+AH27*AG27 -> 0 | AK27: R1 | AL27: Sorbitol* | AM27: 0.7956 | AN27: =IFERROR(VLOOKUP(AL27,'Cost Master List'!$B$2:$P$74,12,),0) -> 1.8143716 | AO27: =+AN27*AM27 -> 1.4435141 | AQ27: R1 | AT27: =IFERROR(VLOOKUP(AR27,'Cost Master List'!$B$2:$P$74,12,),0) -> 0 | AU27: =+AT27*AS27 -> 0 | AW27: R1 | AZ27: =IFERROR(VLOOKUP(AX27,'Cost Master List'!$B$2:$P$74,12,),0) -> 0 | BA27: =+AZ27*AY27 -> 0
A28: R2 | B28: Sun Flower Oil* | C28: 0.95 | D28: =IFERROR(VLOOKUP(B28,'Cost Master List'!$B$2:$P$74,12,),0) -> 1.1850115 | E28: =+D28*C28 -> 1.1257609 | G28: R2 | H28: Maltodextrin M-100 IP (Brenntag) | I28: 0.125 | J28: =IFERROR(VLOOKUP(H28,'Cost Master List'!$B$2:$P$74,12,),0) -> 0.83914688 | K28: =+J28*I28 -> 0.10489336 | M28: R2 | P28: =IFERROR(VLOOKUP(N28,'Cost Master List'!$B$2:$P$74,12,),0) -> 0 | Q28: =+P28*O28 -> 0 | S28: R2 | V28: =IFERROR(VLOOKUP(T28,'Cost Master List'!$B$2:$P$74,12,),0) -> 0 | W28: =+V28*U28 -> 0 | Y28: R2 | AB28: =IFERROR(VLOOKUP(Z28,'Cost Master List'!$B$2:$P$74,12,),0) -> 0 | AC28: =+AB28*AA28 -> 0 | AE28: R2 | AH28: =IFERROR(VLOOKUP(AF28,'Cost Master List'!$B$2:$P$74,12,),0) -> 0 | AI28: =+AH28*AG28 -> 0 | AK28: R2 | AL28: DI Water | AM28: 0.1094 | AN28: =IFERROR(VLOOKUP(AL28,'Cost Master List'!$B$2:$P$74,12,),0) -> 0.22679645 | AO28: =+AN28*AM28 -> 0.024811532 | AQ28: R2 | AT28: =IFERROR(VLOOKUP(AR28,'Cost Master List'!$B$2:$P$74,12,),0) -> 0 | AU28: =+AT28*AS28 -> 0 | AW28: R2 | AZ28: =IFERROR(VLOOKUP(AX28,'Cost Master List'!$B$2:$P$74,12,),0) -> 0 | BA28: =+AZ28*AY28 -> 0
A29: R3 | D29: =IFERROR(VLOOKUP(B29,'Cost Master List'!$B$2:$P$74,12,),0) -> 0 | E29: =+D29*C29 -> 0 | G29: R3 | J29: =IFERROR(VLOOKUP(H29,'Cost Master List'!$B$2:$P$74,12,),0) -> 0 | K29: =+J29*I29 -> 0 | M29: R3 | P29: =IFERROR(VLOOKUP(N29,'Cost Master List'!$B$2:$P$74,12,),0) -> 0 | Q29: =+P29*O29 -> 0 | S29: R3 | V29: =IFERROR(VLOOKUP(T29,'Cost Master List'!$B$2:$P$74,12,),0) -> 0 | W29: =+V29*U29 -> 0 | Y29: R3 | AB29: =IFERROR(VLOOKUP(Z29,'Cost Master List'!$B$2:$P$74,12,),0) -> 0 | AC29: =+AB29*AA29 -> 0 | AE29: R3 | AH29: =IFERROR(VLOOKUP(AF29,'Cost Master List'!$B$2:$P$74,12,),0) -> 0 | AI29: =+AH29*AG29 -> 0 | AK29: R3 | AL29: Potassium Sorbate (Brenntag) | AM29: 0.002 | AN29: =IFERROR(VLOOKUP(AL29,'Cost Master List'!$B$2:$P$74,12,),0) -> 2.0184884 | AO29: =+AN29*AM29 -> 0.0040369769 | AQ29: R3 | AT29: =IFERROR(VLOOKUP(AR29,'Cost Master List'!$B$2:$P$74,12,),0) -> 0 | AU29: =+AT29*AS29 -> 0 | AW29: R3 | AZ29: =IFERROR(VLOOKUP(AX29,'Cost Master List'!$B$2:$P$74,12,),0) -> 0 | BA29: =+AZ29*AY29 -> 0
A30: R4 | D30: =IFERROR(VLOOKUP(B30,'Cost Master List'!$B$2:$P$74,12,),0) -> 0 | E30: =+D30*C30 -> 0 | G30: R4 | J30: =IFERROR(VLOOKUP(H30,'Cost Master List'!$B$2:$P$74,12,),0) -> 0 | K30: =+J30*I30 -> 0 | M30: R4 | P30: =IFERROR(VLOOKUP(N30,'Cost Master List'!$B$2:$P$74,12,),0) -> 0 | Q30: =+P30*O30 -> 0 | S30: R4 | V30: =IFERROR(VLOOKUP(T30,'Cost Master List'!$B$2:$P$74,12,),0) -> 0 | W30: =+V30*U30 -> 0 | Y30: R4 | AB30: =IFERROR(VLOOKUP(Z30,'Cost Master List'!$B$2:$P$74,12,),0) -> 0 | AC30: =+AB30*AA30 -> 0 | AE30: R4 | AH30: =IFERROR(VLOOKUP(AF30,'Cost Master List'!$B$2:$P$74,12,),0) -> 0 | AI30: =+AH30*AG30 -> 0 | AK30: R4 | AL30: Citric Acid* | AM30: 0.003 | AN30: =IFERROR(VLOOKUP(AL30,'Cost Master List'!$B$2:$P$74,12,),0) -> 4.5359291 | AO30: =+AN30*AM30 -> 0.013607787 | AQ30: R4 | AT30: =IFERROR(VLOOKUP(AR30,'Cost Master List'!$B$2:$P$74,12,),0) -> 0 | AU30: =+AT30*AS30 -> 0 | AW30: R4 | AZ30: =IFERROR(VLOOKUP(AX30,'Cost Master List'!$B$2:$P$74,12,),0) -> 0 | BA30: =+AZ30*AY30 -> 0
A31: R5 | D31: =IFERROR(VLOOKUP(B31,'Cost Master List'!$B$2:$P$74,12,),0) -> 0 | E31: =+D31*C31 -> 0 | G31: R5 | J31: =IFERROR(VLOOKUP(H31,'Cost Master List'!$B$2:$P$74,12,),0) -> 0 | K31: =+J31*I31 -> 0 | M31: R5 | P31: =IFERROR(VLOOKUP(N31,'Cost Master List'!$B$2:$P$74,12,),0) -> 0 | Q31: =+P31*O31 -> 0 | S31: R5 | V31: =IFERROR(VLOOKUP(T31,'Cost Master List'!$B$2:$P$74,12,),0) -> 0 | W31: =+V31*U31 -> 0 | Y31: R5 | AB31: =IFERROR(VLOOKUP(Z31,'Cost Master List'!$B$2:$P$74,12,),0) -> 0 | AC31: =+AB31*AA31 -> 0 | AE31: R5 | AH31: =IFERROR(VLOOKUP(AF31,'Cost Master List'!$B$2:$P$74,12,),0) -> 0 | AI31: =+AH31*AG31 -> 0 | AK31: R5 | AL31: Black Carrot EV100 (Nutracean) | AM31: 0.09 | AN31: =IFERROR(VLOOKUP(AL31,'Cost Master List'!$B$2:$P$74,12,),0) -> 76.076603 | AO31: =+AN31*AM31 -> 6.8468942 | AQ31: R5 | AT31: =IFERROR(VLOOKUP(AR31,'Cost Master List'!$B$2:$P$74,12,),0) -> 0 | AU31: =+AT31*AS31 -> 0 | AW31: R5 | AZ31: =IFERROR(VLOOKUP(AX31,'Cost Master List'!$B$2:$P$74,12,),0) -> 0 | BA31: =+AZ31*AY31 -> 0
A32: P1 | B32: 5 Gallon Pails | D32: =IFERROR(VLOOKUP('Manufactured Items Models'!B32,'Cost Master List'!$B$84:$L$98,11,FALSE),0) -> 9.68 | E32: =+D32/$A$26 -> 0.242 | G32: P1 | H32: 15x15x15 box | J32: =IFERROR(VLOOKUP('Manufactured Items Models'!H32,'Cost Master List'!$B$84:$L$98,11,FALSE),0) -> 2.47 | K32: =+J32/$G$26 -> 0.06175 | M32: P1 | P32: =IFERROR(VLOOKUP('Manufactured Items Models'!N32,'Cost Master List'!$B$84:$L$98,11,FALSE),0) -> 0 | Q32: =+P32/$G$14 -> 0 | S32: P1 | V32: =IFERROR(VLOOKUP('Manufactured Items Models'!T32,'Cost Master List'!$B$84:$L$98,11,FALSE),0) -> 0 | W32: =+V32/$G$14 -> 0 | Y32: P1 | AB32: =IFERROR(VLOOKUP('Manufactured Items Models'!Z32,'Cost Master List'!$B$84:$L$98,11,FALSE),0) -> 0 | AC32: =+AB32/$G$14 -> 0 | AE32: P1 | AH32: =IFERROR(VLOOKUP('Manufactured Items Models'!AF32,'Cost Master List'!$B$84:$L$98,11,FALSE),0) -> 0 | AI32: =+AH32/$G$14 -> 0 | AK32: P1 | AL32: 5 Gallon Pails | AN32: =IFERROR(VLOOKUP('Manufactured Items Models'!AL32,'Cost Master List'!$B$84:$L$98,11,FALSE),0) -> 9.68 | AO32: =+AN32/$G$14 -> 0.242 | AQ32: P1 | AT32: =IFERROR(VLOOKUP('Manufactured Items Models'!AR32,'Cost Master List'!$B$84:$L$98,11,FALSE),0) -> 0 | AU32: =+AT32/$G$14 -> 0 | AW32: P1 | AZ32: =IFERROR(VLOOKUP('Manufactured Items Models'!AX32,'Cost Master List'!$B$84:$L$98,11,FALSE),0) -> 0 | BA32: =+AZ32/$G$14 -> 0
A33: P2 | D33: =IFERROR(VLOOKUP('Manufactured Items Models'!B33,'Cost Master List'!$B$84:$L$98,11,FALSE),0) -> 0 | E33: =+D33/$A$26 -> 0 | G33: P2 | H33: Blue USFDA Poly Bag 34x40x.004 | J33: =IFERROR(VLOOKUP('Manufactured Items Models'!H33,'Cost Master List'!$B$84:$L$98,11,FALSE),0) -> 0.678 | K33: =+J33/$G$26 -> 0.01695 | M33: P2 | P33: =IFERROR(VLOOKUP('Manufactured Items Models'!N33,'Cost Master List'!$B$84:$L$98,11,FALSE),0) -> 0 | Q33: =+P33/$G$14 -> 0 | S33: P2 | V33: =IFERROR(VLOOKUP('Manufactured Items Models'!T33,'Cost Master List'!$B$84:$L$98,11,FALSE),0) -> 0 | W33: =+V33/$G$14 -> 0 | Y33: P2 | AB33: =IFERROR(VLOOKUP('Manufactured Items Models'!Z33,'Cost Master List'!$B$84:$L$98,11,FALSE),0) -> 0 | AC33: =+AB33/$G$14 -> 0 | AE33: P2 | AH33: =IFERROR(VLOOKUP('Manufactured Items Models'!AF33,'Cost Master List'!$B$84:$L$98,11,FALSE),0) -> 0 | AI33: =+AH33/$G$14 -> 0 | AK33: P2 | AN33: =IFERROR(VLOOKUP('Manufactured Items Models'!AL33,'Cost Master List'!$B$84:$L$98,11,FALSE),0) -> 0 | AO33: =+AN33/$G$14 -> 0 | AQ33: P2 | AT33: =IFERROR(VLOOKUP('Manufactured Items Models'!AR33,'Cost Master List'!$B$84:$L$98,11,FALSE),0) -> 0 | AU33: =+AT33/$G$14 -> 0 | AW33: P2 | AZ33: =IFERROR(VLOOKUP('Manufactured Items Models'!AX33,'Cost Master List'!$B$84:$L$98,11,FALSE),0) -> 0 | BA33: =+AZ33/$G$14 -> 0
A34: P3 | D34: =IFERROR(VLOOKUP('Manufactured Items Models'!B34,'Cost Master List'!$B$84:$L$98,11,FALSE),0) -> 0 | E34: =+D34/$A$26 -> 0 | G34: P3 | J34: =IFERROR(VLOOKUP('Manufactured Items Models'!H34,'Cost Master List'!$B$84:$L$98,11,FALSE),0) -> 0 | K34: =+J34/$G$26 -> 0 | M34: P3 | P34: =IFERROR(VLOOKUP('Manufactured Items Models'!N34,'Cost Master List'!$B$84:$L$98,11,FALSE),0) -> 0 | Q34: =+P34/$G$14 -> 0 | S34: P3 | V34: =IFERROR(VLOOKUP('Manufactured Items Models'!T34,'Cost Master List'!$B$84:$L$98,11,FALSE),0) -> 0 | W34: =+V34/$G$14 -> 0 | Y34: P3 | AB34: =IFERROR(VLOOKUP('Manufactured Items Models'!Z34,'Cost Master List'!$B$84:$L$98,11,FALSE),0) -> 0 | AC34: =+AB34/$G$14 -> 0 | AE34: P3 | AH34: =IFERROR(VLOOKUP('Manufactured Items Models'!AF34,'Cost Master List'!$B$84:$L$98,11,FALSE),0) -> 0 | AI34: =+AH34/$G$14 -> 0 | AK34: P3 | AN34: =IFERROR(VLOOKUP('Manufactured Items Models'!AL34,'Cost Master List'!$B$84:$L$98,11,FALSE),0) -> 0 | AO34: =+AN34/$G$14 -> 0 | AQ34: P3 | AT34: =IFERROR(VLOOKUP('Manufactured Items Models'!AR34,'Cost Master List'!$B$84:$L$98,11,FALSE),0) -> 0 | AU34: =+AT34/$G$14 -> 0 | AW34: P3 | AZ34: =IFERROR(VLOOKUP('Manufactured Items Models'!AX34,'Cost Master List'!$B$84:$L$98,11,FALSE),0) -> 0 | BA34: =+AZ34/$G$14 -> 0
A35: Labor | E35: 1 | G35: Labor | K35: 1 | M35: Labor | Q35: 1 | S35: Labor | W35: 1 | Y35: Labor | AC35: 1 | AE35: Labor | AI35: 1 | AK35: Labor | AO35: 1 | AQ35: Labor | AU35: 1 | AW35: Labor | BA35: 1
B36: =+B26 -> Annatto Extract P2404 | D36: Cost/lb | E36: =+SUM(E27:E35) -> 10.138941 | H36: Natural Red D1307 (40) | J36: Cost/lb | K36: =+SUM(K27:K35) -> 7.6097008 | P36: Cost/lb | Q36: =+SUM(Q27:Q35) -> 1 | V36: Cost/lb | W36: =+SUM(W27:W35) -> 1 | AB36: Cost/lb | AC36: =+SUM(AC27:AC35) -> 1 | AH36: Cost/lb | AI36: =+SUM(AI27:AI35) -> 1 | AN36: Cost/lb | AO36: =+SUM(AO27:AO35) -> 9.5748646 | AT36: Cost/lb | AU36: =+SUM(AU27:AU35) -> 1 | AZ36: Cost/lb | BA36: =+SUM(BA27:BA35) -> 1
A38: 8 | B38: Annatto Extract P1411 | C38: Composition | D38: Price/lb | E38: Formula Cost | I38: Composition | J38: Price/lb | K38: Formula Cost | O38: Composition | P38: Price/lb | Q38: Formula Cost | U38: Composition | V38: Price/lb | W38: Formula Cost | AA38: Composition | AB38: Price/lb | AC38: Formula Cost | AG38: Composition | AH38: Price/lb | AI38: Formula Cost | AM38: Composition | AN38: Price/lb | AO38: Formula Cost | AS38: Composition | AT38: Price/lb | AU38: Formula Cost | AY38: Composition | AZ38: Price/lb | BA38: Formula Cost
A39: R1 | B39: Annatto Extract WS5 (Cyber Colors) | C39: 0.21 | D39: =IFERROR(VLOOKUP(B39,'Cost Master List'!$B$2:$P$74,12,),0) -> 6.1053606 | E39: =+D39*C39 -> 1.2821257 | G39: R1 | J39: =IFERROR(VLOOKUP(H39,'Cost Master List'!$B$2:$P$74,12,),0) -> 0 | K39: =+J39*I39 -> 0 | M39: R1 | P39: =IFERROR(VLOOKUP(N39,'Cost Master List'!$B$2:$P$74,12,),0) -> 0 | Q39: =+P39*O39 -> 0 | S39: R1 | V39: =IFERROR(VLOOKUP(T39,'Cost Master List'!$B$2:$P$74,12,),0) -> 0 | W39: =+V39*U39 -> 0 | Y39: R1 | AB39: =IFERROR(VLOOKUP(Z39,'Cost Master List'!$B$2:$P$74,12,),0) -> 0 | AC39: =+AB39*AA39 -> 0 | AE39: R1 | AH39: =IFERROR(VLOOKUP(AF39,'Cost Master List'!$B$2:$P$74,12,),0) -> 0 | AI39: =+AH39*AG39 -> 0 | AK39: R1 | AN39: =IFERROR(VLOOKUP(AL39,'Cost Master List'!$B$2:$P$74,12,),0) -> 0 | AO39: =+AN39*AM39 -> 0 | AQ39: R1 | AT39: =IFERROR(VLOOKUP(AR39,'Cost Master List'!$B$2:$P$74,12,),0) -> 0 | AU39: =+AT39*AS39 -> 0 | AW39: R1 | AZ39: =IFERROR(VLOOKUP(AX39,'Cost Master List'!$B$2:$P$74,12,),0) -> 0 | BA39: =+AZ39*AY39 -> 0
A40: R2 | B40: DI Water | C40: 0.79 | D40: =IFERROR(VLOOKUP(B40,'Cost Master List'!$B$2:$P$74,12,),0) -> 0.22679645 | E40: =+D40*C40 -> 0.1791692 | G40: R2 | J40: =IFERROR(VLOOKUP(H40,'Cost Master List'!$B$2:$P$74,12,),0) -> 0 | K40: =+J40*I40 -> 0 | M40: R2 | P40: =IFERROR(VLOOKUP(N40,'Cost Master List'!$B$2:$P$74,12,),0) -> 0 | Q40: =+P40*O40 -> 0 | S40: R2 | V40: =IFERROR(VLOOKUP(T40,'Cost Master List'!$B$2:$P$74,12,),0) -> 0 | W40: =+V40*U40 -> 0 | Y40: R2 | AB40: =IFERROR(VLOOKUP(Z40,'Cost Master List'!$B$2:$P$74,12,),0) -> 0 | AC40: =+AB40*AA40 -> 0 | AE40: R2 | AH40: =IFERROR(VLOOKUP(AF40,'Cost Master List'!$B$2:$P$74,12,),0) -> 0 | AI40: =+AH40*AG40 -> 0 | AK40: R2 | AN40: =IFERROR(VLOOKUP(AL40,'Cost Master List'!$B$2:$P$74,12,),0) -> 0 | AO40: =+AN40*AM40 -> 0 | AQ40: R2 | AT40: =IFERROR(VLOOKUP(AR40,'Cost Master List'!$B$2:$P$74,12,),0) -> 0 | AU40: =+AT40*AS40 -> 0 | AW40: R2 | AZ40: =IFERROR(VLOOKUP(AX40,'Cost Master List'!$B$2:$P$74,12,),0) -> 0 | BA40: =+AZ40*AY40 -> 0
A41: R3 | D41: =IFERROR(VLOOKUP(B41,'Cost Master List'!$B$2:$P$74,12,),0) -> 0 | E41: =+D41*C41 -> 0 | G41: R3 | J41: =IFERROR(VLOOKUP(H41,'Cost Master List'!$B$2:$P$74,12,),0) -> 0 | K41: =+J41*I41 -> 0 | M41: R3 | P41: =IFERROR(VLOOKUP(N41,'Cost Master List'!$B$2:$P$74,12,),0) -> 0 | Q41: =+P41*O41 -> 0 | S41: R3 | V41: =IFERROR(VLOOKUP(T41,'Cost Master List'!$B$2:$P$74,12,),0) -> 0 | W41: =+V41*U41 -> 0 | Y41: R3 | AB41: =IFERROR(VLOOKUP(Z41,'Cost Master List'!$B$2:$P$74,12,),0) -> 0 | AC41: =+AB41*AA41 -> 0 | AE41: R3 | AH41: =IFERROR(VLOOKUP(AF41,'Cost Master List'!$B$2:$P$74,12,),0) -> 0 | AI41: =+AH41*AG41 -> 0 | AK41: R3 | AN41: =IFERROR(VLOOKUP(AL41,'Cost Master List'!$B$2:$P$74,12,),0) -> 0 | AO41: =+AN41*AM41 -> 0 | AQ41: R3 | AT41: =IFERROR(VLOOKUP(AR41,'Cost Master List'!$B$2:$P$74,12,),0) -> 0 | AU41: =+AT41*AS41 -> 0 | AW41: R3 | AZ41: =IFERROR(VLOOKUP(AX41,'Cost Master List'!$B$2:$P$74,12,),0) -> 0 | BA41: =+AZ41*AY41 -> 0
A42: R4 | D42: =IFERROR(VLOOKUP(B42,'Cost Master List'!$B$2:$P$74,12,),0) -> 0 | E42: =+D42*C42 -> 0 | G42: R4 | J42: =IFERROR(VLOOKUP(H42,'Cost Master List'!$B$2:$P$74,12,),0) -> 0 | K42: =+J42*I42 -> 0 | M42: R4 | P42: =IFERROR(VLOOKUP(N42,'Cost Master List'!$B$2:$P$74,12,),0) -> 0 | Q42: =+P42*O42 -> 0 | S42: R4 | V42: =IFERROR(VLOOKUP(T42,'Cost Master List'!$B$2:$P$74,12,),0) -> 0 | W42: =+V42*U42 -> 0 | Y42: R4 | AB42: =IFERROR(VLOOKUP(Z42,'Cost Master List'!$B$2:$P$74,12,),0) -> 0 | AC42: =+AB42*AA42 -> 0 | AE42: R4 | AH42: =IFERROR(VLOOKUP(AF42,'Cost Master List'!$B$2:$P$74,12,),0) -> 0 | AI42: =+AH42*AG42 -> 0 | AK42: R4 | AN42: =IFERROR(VLOOKUP(AL42,'Cost Master List'!$B$2:$P$74,12,),0) -> 0 | AO42: =+AN42*AM42 -> 0 | AQ42: R4 | AT42: =IFERROR(VLOOKUP(AR42,'Cost Master List'!$B$2:$P$74,12,),0) -> 0 | AU42: =+AT42*AS42 -> 0 | AW42: R4 | AZ42: =IFERROR(VLOOKUP(AX42,'Cost Master List'!$B$2:$P$74,12,),0) -> 0 | BA42: =+AZ42*AY42 -> 0
A43: R5 | D43: =IFERROR(VLOOKUP(B43,'Cost Master List'!$B$2:$P$74,12,),0) -> 0 | E43: =+D43*C43 -> 0 | G43: R5 | J43: =IFERROR(VLOOKUP(H43,'Cost Master List'!$B$2:$P$74,12,),0) -> 0 | K43: =+J43*I43 -> 0 | M43: R5 | P43: =IFERROR(VLOOKUP(N43,'Cost Master List'!$B$2:$P$74,12,),0) -> 0 | Q43: =+P43*O43 -> 0 | S43: R5 | V43: =IFERROR(VLOOKUP(T43,'Cost Master List'!$B$2:$P$74,12,),0) -> 0 | W43: =+V43*U43 -> 0 | Y43: R5 | AB43: =IFERROR(VLOOKUP(Z43,'Cost Master List'!$B$2:$P$74,12,),0) -> 0 | AC43: =+AB43*AA43 -> 0 | AE43: R5 | AH43: =IFERROR(VLOOKUP(AF43,'Cost Master List'!$B$2:$P$74,12,),0) -> 0 | AI43: =+AH43*AG43 -> 0 | AK43: R5 | AN43: =IFERROR(VLOOKUP(AL43,'Cost Master List'!$B$2:$P$74,12,),0) -> 0 | AO43: =+AN43*AM43 -> 0 | AQ43: R5 | AT43: =IFERROR(VLOOKUP(AR43,'Cost Master List'!$B$2:$P$74,12,),0) -> 0 | AU43: =+AT43*AS43 -> 0 | AW43: R5 | AZ43: =IFERROR(VLOOKUP(AX43,'Cost Master List'!$B$2:$P$74,12,),0) -> 0 | BA43: =+AZ43*AY43 -> 0
...

Sheet Customer Pricing
A1: Customer | B1: Close Probability | C1: Distributed or Manufactured? | D1: Product | E1: Cost | F1: Additional Cost (per lb) | G1: Margin | H1: Price | I1: Volume | J1: Annual Revenue | K1: Gross Profit | L1: % of Volume to hit 2026 | M1: Agreement | N1: Incoterms | O1: 1st Order Ship | P1: Order Pattern | Q1: Notes | R1: Date Updated | Z1: {=_xlfn._xlws.SORT(_xlfn.UNIQUE(_xlfn._xlws.FILTER('Cost Master List'!$B:$B,'Cost Master List'!$B:$B<>"")))} -> 1 Gallon Jug & Box Combo | AA1: {=_xlfn.LET( _xlpm.rng,'Manufactured Items Models'!$B:$BA, _xlpm.rows,{12;24;36;48;60;72;84;96;108}, _xlpm.itemCols,{1,7,13,19,25,31,37,43,49}, _xlpm.items,_xlfn.TOCOL(INDEX(_xlpm.rng,_xlpm.rows,_xlpm.itemCols),1), _xlfn._xlws.FILTER(_xlpm.items,_xlpm.items<>"") )} -> Annatto Extract P2401 (8) | AB1: {=_xlfn.LET( _xlpm.rng,'Manufactured Items Models'!$B:$BA, _xlpm.rows,{12;24;36;48;60;72;84;96;108}, _xlpm.itemCols,{1,7,13,19,25,31,37,43,49}, _xlpm.priceCols,_xlpm.itemCols+3, _xlpm.items,_xlfn.TOCOL(INDEX(_xlpm.rng,_xlpm.rows,_xlpm.itemCols),1), _xlpm.prices,_xlfn.TOCOL(INDEX(_xlpm.rng,_xlpm.rows,_xlpm.priceCols),1), _xlpm.mask,_xlpm.items<>"", _xlfn._xlws.FILTER(_xlpm.items,_xlpm.mask) )} -> Annatto Extract P2401 (8) | AC1: {=_xlfn.LET( _xlpm.rng,'Manufactured Items Models'!$B:$BA, _xlpm.rows,{12;24;36;48;60;72;84;96;108}, _xlpm.itemCols,{1,7,13,19,25,31,37,43,49}, _xlpm.priceCols,_xlpm.itemCols+3, _xlpm.items,_xlfn.TOCOL(INDEX(_xlpm.rng,_xlpm.rows,_xlpm.itemCols),1), _xlpm.prices,_xlfn.TOCOL(INDEX(_xlpm.rng,_xlpm.rows,_xlpm.priceCols),1), _xlpm.mask,_xlpm.items<>"", _xlfn._xlws.FILTER(_xlpm.prices,_xlpm.mask) )} -> #VALUE!
A2: Flavorchem | B2: 0.5 | C2: Manufactured | D2: Annatto Extract P1428 (8) | E2: {=IF(LOWER(TRIM($C2))="distributed",_xlfn.XLOOKUP($D2,'Cost Master List'!$B:$B,'Cost Master List'!$M:$M,"",0),_xlfn.LET(_xlpm.norm,_xlfn.LAMBDA(_xlpm.x,TRIM(SUBSTITUTE(_xlpm.x,CHAR(160),""))),_xlpm.rng,'Manufactured Items Models'!$B:$BA,_xlpm.rows,{12;24;36;48;60;72;84;96;108},_xlpm.itemCols,{1,7,13,19,25,31,37,43,49},_xlpm.priceCols,_xlpm.itemCols+3,_xlpm.items,INDEX(_xlpm.rng,_xlpm.rows,_xlpm.itemCols),_xlpm.prices,INDEX(_xlpm.rng,_xlpm.rows,_xlpm.priceCols),_xlpm.needle,_xlpm.norm($D2),_xlpm.hit,SUMPRODUCT((_xlpm.norm(_xlpm.items)=_xlpm.needle)*_xlpm.prices),IF(_xlpm.hit=0,"",_xlpm.hit)))} -> 3.7782221 | F2: 0 | G2: 0.28585906 | H2: =IF(OR(E2="",G2=""),0,(E2+F2)/(1-G2)) -> 5.2905833 | I2: 16000 | J2: =+I2*H2 -> 84649.332 | K2: =+J2*G2 -> 24197.779 | L2: 0.9 | M2: Quoted | O2: February | P2: Every Month | T2: Revenue Total | U2: =+SUM(J2:J1048576) -> 6479764.9 | Z2: 12x12x16 box | AA2: Natural Red D1303 (40) | AB2: Natural Red D1303 (40)
A3: Flavorchem | B3: 0.5 | C3: Distributed | D3: Annatto Extract P1315 (IFF) | E3: {=IF(LOWER(TRIM($C3))="distributed",_xlfn.XLOOKUP($D3,'Cost Master List'!$B:$B,'Cost Master List'!$M:$M,"",0),_xlfn.LET(_xlpm.norm,_xlfn.LAMBDA(_xlpm.x,TRIM(SUBSTITUTE(_xlpm.x,CHAR(160),""))),_xlpm.rng,'Manufactured Items Models'!$B:$BA,_xlpm.rows,{12;24;36;48;60;72;84;96;108},_xlpm.itemCols,{1,7,13,19,25,31,37,43,49},_xlpm.priceCols,_xlpm.itemCols+3,_xlpm.items,INDEX(_xlpm.rng,_xlpm.rows,_xlpm.itemCols),_xlpm.prices,INDEX(_xlpm.rng,_xlpm.rows,_xlpm.priceCols),_xlpm.needle,_xlpm.norm($D3),_xlpm.hit,SUMPRODUCT((_xlpm.norm(_xlpm.items)=_xlpm.needle)*_xlpm.prices),IF(_xlpm.hit=0,"",_xlpm.hit)))} -> 26.0952 | F3: 0 | G3: 0.17811387 | H3: =IF(OR(E3="",G3=""),0,(E3+F3)/(1-G3)) -> 31.750384 | I3: 1000 | J3: =+I3*H3 -> 31750.384 | K3: =+J3*G3 -> 5655.1837 | L3: 1 | M3: Quoted | O3: February | P3: Semi-Annual | T3: Gross Profit | U3: =+SUM(K2:K1048576) -> 2192614.7 | Z3: 15x15x15 box | AA3: Natural BP N1399 (11) | AB3: Natural BP N1399 (11)
A4: Black Label | B4: 0.1 | C4: Distributed | D4: Natural Green J1410 (Cyber Colors) | E4: {=IF(LOWER(TRIM($C4))="distributed",_xlfn.XLOOKUP($D4,'Cost Master List'!$B:$B,'Cost Master List'!$M:$M,"",0),_xlfn.LET(_xlpm.norm,_xlfn.LAMBDA(_xlpm.x,TRIM(SUBSTITUTE(_xlpm.x,CHAR(160),""))),_xlpm.rng,'Manufactured Items Models'!$B:$BA,_xlpm.rows,{12;24;36;48;60;72;84;96;108},_xlpm.itemCols,{1,7,13,19,25,31,37,43,49},_xlpm.priceCols,_xlpm.itemCols+3,_xlpm.items,INDEX(_xlpm.rng,_xlpm.rows,_xlpm.itemCols),_xlpm.prices,INDEX(_xlpm.rng,_xlpm.rows,_xlpm.priceCols),_xlpm.needle,_xlpm.norm($D4),_xlpm.hit,SUMPRODUCT((_xlpm.norm(_xlpm.items)=_xlpm.needle)*_xlpm.prices),IF(_xlpm.hit=0,"",_xlpm.hit)))} -> 20.375507 | F4: 0 | H4: =IF(OR(E4="",G4=""),0,(E4+F4)/(1-G4)) -> 0 | I4: 1600 | J4: =+I4*H4 -> 0 | K4: =+J4*G4 -> 0 | L4: 0.5 | M4: Quoted | O4: June | P4: Every Other Month | T4: GP % | U4: =+U3/U2 -> 0.33837874 | Z4: 16x12x10 box | AA4: Natural Red A1320 (44) | AB4: Natural Red A1320 (44)
A5: Black Label | B5: 0.6 | C5: Manufactured | D5: Natural Blue L1355 (11) | E5: {=IF(LOWER(TRIM($C5))="distributed",_xlfn.XLOOKUP($D5,'Cost Master List'!$B:$B,'Cost Master List'!$M:$M,"",0),_xlfn.LET(_xlpm.norm,_xlfn.LAMBDA(_xlpm.x,TRIM(SUBSTITUTE(_xlpm.x,CHAR(160),""))),_xlpm.rng,'Manufactured Items Models'!$B:$BA,_xlpm.rows,{12;24;36;48;60;72;84;96;108},_xlpm.itemCols,{1,7,13,19,25,31,37,43,49},_xlpm.priceCols,_xlpm.itemCols+3,_xlpm.items,INDEX(_xlpm.rng,_xlpm.rows,_xlpm.itemCols),_xlpm.prices,INDEX(_xlpm.rng,_xlpm.rows,_xlpm.priceCols),_xlpm.needle,_xlpm.norm($D5),_xlpm.hit,SUMPRODUCT((_xlpm.norm(_xlpm.items)=_xlpm.needle)*_xlpm.prices),IF(_xlpm.hit=0,"",_xlpm.hit)))} -> 18.115126 | F5: 0 | G5: 0.47278462 | H5: =IF(OR(E5="",G5=""),0,(E5+F5)/(1-G5)) -> 34.36001 | I5: 1000 | J5: =+I5*H5 -> 34360.01 | K5: =+J5*G5 -> 16244.884 | L5: 1 | M5: Quoted | O5: March | P5: Quarterly | Z5: 30 Gal Fiber Drums | AA5: Natural Red E1430 (44) | AB5: Natural Red E1430 (44)
A6: Black Label | B6: 0 | C6: Manufactured | D6: Natural BP N1399 (11) | E6: {=IF(LOWER(TRIM($C6))="distributed",_xlfn.XLOOKUP($D6,'Cost Master List'!$B:$B,'Cost Master List'!$M:$M,"",0),_xlfn.LET(_xlpm.norm,_xlfn.LAMBDA(_xlpm.x,TRIM(SUBSTITUTE(_xlpm.x,CHAR(160),""))),_xlpm.rng,'Manufactured Items Models'!$B:$BA,_xlpm.rows,{12;24;36;48;60;72;84;96;108},_xlpm.itemCols,{1,7,13,19,25,31,37,43,49},_xlpm.priceCols,_xlpm.itemCols+3,_xlpm.items,INDEX(_xlpm.rng,_xlpm.rows,_xlpm.itemCols),_xlpm.prices,INDEX(_xlpm.rng,_xlpm.rows,_xlpm.priceCols),_xlpm.needle,_xlpm.norm($D6),_xlpm.hit,SUMPRODUCT((_xlpm.norm(_xlpm.items)=_xlpm.needle)*_xlpm.prices),IF(_xlpm.hit=0,"",_xlpm.hit)))} -> 39.444965 | F6: 0 | G6: 0.62144819 | H6: =IF(OR(E6="",G6=""),0,(E6+F6)/(1-G6)) -> 104.19965 | J6: =+I6*H6 -> 0 | K6: =+J6*G6 -> 0 | L6: 0 | M6: Quoted | Z6: 5 Gallon Pails | AA6: Natural Blue L1355 (11) | AB6: Natural Blue L1355 (11)
